Workbook

Sheet Index
G20: Pricelist January '25

Sheet Z9
C3: Format
D4: FX
C5: Megapixels
D6: 45.7 MP
C7: Continuous Shooting
D8: 20 FPS Raw
D9: 120 FPS JPEG
C10: ISO
D11: ISO 64–25600, ISO Expandable to 102,400
C13: Video
D14: 8K UHD videos
C16: Memory
D17: Dual CFexpress Type B card slots
C19: Monitor Size
D20: 3.2 Inch V/H Tilt Touch-LCD | G20: The Fastest, most powerful Nikon - Ever.
C22: Order Code | G22: Details | I22: Product Code | J22: Barcode | K22: Dealer (Export)
D24: CAMNIILCZ9 | G24: =IFERROR(VLOOKUP($D24,'Master Sheet'!$B:$AA,3,FALSE),"") -> Nikon Z9 Mirrorless Digital Camera Body | I24: =IFERROR(VLOOKUP($D24,'Master Sheet'!$B:$AA,2,FALSE),"") -> VOA080AM | J24: =IFERROR(VLOOKUP($D24,'Master Sheet'!$B:$AA,5,FALSE),"") -> 4960759912282 | K24: =IFERROR(VLOOKUP($D24,'Master Sheet'!$B:$AA,8,FALSE),"") -> 97829.955
G25: =IFERROR(VLOOKUP($D25,'Master Sheet'!$B:$AA,3,FALSE),"") | I25: =IFERROR(VLOOKUP($D25,'Master Sheet'!$B:$AA,2,FALSE),"") | J25: =IFERROR(VLOOKUP($D25,'Master Sheet'!$B:$AA,5,FALSE),"") | K25: =IFERROR(VLOOKUP($D25,'Master Sheet'!$B:$AA,8,FALSE),"")
C26: Body Cap
D27: CAMNIACILCBFN1 | G27: =IFERROR(VLOOKUP($D27,'Master Sheet'!$B:$AA,3,FALSE),"") -> BF-N1 Body Cap (Z-Series) | I27: =IFERROR(VLOOKUP($D27,'Master Sheet'!$B:$AA,2,FALSE),"") -> VOD00101 | J27: =IFERROR(VLOOKUP($D27,'Master Sheet'!$B:$AA,5,FALSE),"") -> 4960759901002 | K27: =IFERROR(VLOOKUP($D27,'Master Sheet'!$B:$AA,8,FALSE),"") -> 116.955
C29: Lens Adapter
D30: CAMNIACILCFTZII | G30: =IFERROR(VLOOKUP($D30,'Master Sheet'!$B:$AA,3,FALSE),"") -> FTZ II Mount Adapter | I30: =IFERROR(VLOOKUP($D30,'Master Sheet'!$B:$AA,2,FALSE),"") -> JMA905DA | J30: =IFERROR(VLOOKUP($D30,'Master Sheet'!$B:$AA,5,FALSE),"") -> 018208042647 | K30: =IFERROR(VLOOKUP($D30,'Master Sheet'!$B:$AA,8,FALSE),"") -> 4049.955
G31: =IFERROR(VLOOKUP($D31,'Master Sheet'!$B:$AA,3,FALSE),"") | I31: =IFERROR(VLOOKUP($D31,'Master Sheet'!$B:$AA,2,FALSE),"") | J31: =IFERROR(VLOOKUP($D31,'Master Sheet'!$B:$AA,5,FALSE),"") | K31: =IFERROR(VLOOKUP($D31,'Master Sheet'!$B:$AA,8,FALSE),"")
C32: Lenses
G33: (See Mirrorless Lenses Pricelist Sheets) | I33: =IFERROR(VLOOKUP($D33,'Master Sheet'!$B:$AA,2,FALSE),"") | J33: =IFERROR(VLOOKUP($D33,'Master Sheet'!$B:$AA,5,FALSE),"") | K33: =IFERROR(VLOOKUP($D33,'Master Sheet'!$B:$AA,8,FALSE),"")
G34: =IFERROR(VLOOKUP($D34,'Master Sheet'!$B:$AA,3,FALSE),"") | I34: =IFERROR(VLOOKUP($D34,'Master Sheet'!$B:$AA,2,FALSE),"") | J34: =IFERROR(VLOOKUP($D34,'Master Sheet'!$B:$AA,5,FALSE),"") | K34: =IFERROR(VLOOKUP($D34,'Master Sheet'!$B:$AA,8,FALSE),"")
C35: Speedlights/Flashes
G36: (See Speedlight Pricelist Sheets) | I36: =IFERROR(VLOOKUP($D36,'Master Sheet'!$B:$AA,2,FALSE),"") | J36: =IFERROR(VLOOKUP($D36,'Master Sheet'!$B:$AA,5,FALSE),"") | K36: =IFERROR(VLOOKUP($D36,'Master Sheet'!$B:$AA,8,FALSE),"")
G37: =IFERROR(VLOOKUP($D37,'Master Sheet'!$B:$AA,3,FALSE),"") | I37: =IFERROR(VLOOKUP($D37,'Master Sheet'!$B:$AA,2,FALSE),"") | J37: =IFERROR(VLOOKUP($D37,'Master Sheet'!$B:$AA,5,FALSE),"") | K37: =IFERROR(VLOOKUP($D37,'Master Sheet'!$B:$AA,8,FALSE),"")
C38: Power Accessories
D39: CAMNIACILCBL7 | G39: =IFERROR(VLOOKUP($D39,'Master Sheet'!$B:$AA,3,FALSE),"") -> BL-7-BATTERY CHAMBER COVER | I39: =IFERROR(VLOOKUP($D39,'Master Sheet'!$B:$AA,2,FALSE),"") -> VFD10401 | J39: =IFERROR(VLOOKUP($D39,'Master Sheet'!$B:$AA,5,FALSE),"") -> 018208272235 | K39: =IFERROR(VLOOKUP($D39,'Master Sheet'!$B:$AA,8,FALSE),"") -> 638.955
D40: CAMNIACENEL18D | G40: =IFERROR(VLOOKUP($D40,'Master Sheet'!$B:$AA,3,FALSE),"") -> EN-EL18D RECHARGEABLE LI-ION BATTERY | I40: =IFERROR(VLOOKUP($D40,'Master Sheet'!$B:$AA,2,FALSE),"") -> VFB12902 | J40: =IFERROR(VLOOKUP($D40,'Master Sheet'!$B:$AA,5,FALSE),"") -> 4960759909220 | K40: =IFERROR(VLOOKUP($D40,'Master Sheet'!$B:$AA,8,FALSE),"") -> 4859.955
D41: CAMNIACILCMH33 | G41: =IFERROR(VLOOKUP($D41,'Master Sheet'!$B:$AA,3,FALSE),"") -> MH-33 BATTERY CHARGER - EN-EL18D Battery | I41: =IFERROR(VLOOKUP($D41,'Master Sheet'!$B:$AA,2,FALSE),"") -> VEA02502 | J41: =IFERROR(VLOOKUP($D41,'Master Sheet'!$B:$AA,5,FALSE),"") -> 4960759909404 | K41: =IFERROR(VLOOKUP($D41,'Master Sheet'!$B:$AA,8,FALSE),"") -> 2240.955
D42: CAMNIACEH6D | G42: =IFERROR(VLOOKUP($D42,'Master Sheet'!$B:$AA,3,FALSE),"") -> AC ADAPTER EH-6D | I42: =IFERROR(VLOOKUP($D42,'Master Sheet'!$B:$AA,2,FALSE),"") -> VEB036EA | J42: =IFERROR(VLOOKUP($D42,'Master Sheet'!$B:$AA,5,FALSE),"") -> 4960759909183 | K42: =IFERROR(VLOOKUP($D42,'Master Sheet'!$B:$AA,8,FALSE),"") -> 4715.955
D43: CAMNIACEP6A | G43: =IFERROR(VLOOKUP($D43,'Master Sheet'!$B:$AA,3,FALSE),"") -> EP-6A POWER SUPPLY CONNECTOR - Z9 | I43: =IFERROR(VLOOKUP($D43,'Master Sheet'!$B:$AA,2,FALSE),"") -> VEB03501 | J43: =IFERROR(VLOOKUP($D43,'Master Sheet'!$B:$AA,5,FALSE),"") -> No Barcode | K43: =IFERROR(VLOOKUP($D43,'Master Sheet'!$B:$AA,8,FALSE),"") -> 6740.955
D44: CAMNIACILCEH7P | G44: =IFERROR(VLOOKUP($D44,'Master Sheet'!$B:$AA,3,FALSE),"") -> Charging AC Adapter EH-7P | I44: =IFERROR(VLOOKUP($D44,'Master Sheet'!$B:$AA,2,FALSE),"") -> VEB029BA | J44: =IFERROR(VLOOKUP($D44,'Master Sheet'!$B:$AA,5,FALSE),"") -> 4960759901958 | K44: =IFERROR(VLOOKUP($D44,'Master Sheet'!$B:$AA,8,FALSE),"") -> 917.955
G45: =IFERROR(VLOOKUP($D45,'Master Sheet'!$B:$AA,3,FALSE),"") | I45: =IFERROR(VLOOKUP($D45,'Master Sheet'!$B:$AA,2,FALSE),"") | J45: =IFERROR(VLOOKUP($D45,'Master Sheet'!$B:$AA,5,FALSE),"") | K45: =IFERROR(VLOOKUP($D45,'Master Sheet'!$B:$AA,8,FALSE),"")
C46: Remotes & Releases
D47: CAMNIACMC30A | G47: =IFERROR(VLOOKUP($D47,'Master Sheet'!$B:$AA,3,FALSE),"") -> MC-30A REMOTE CORD - D4/D4S/D800/E | I47: =IFERROR(VLOOKUP($D47,'Master Sheet'!$B:$AA,2,FALSE),"") -> VDR00601 | J47: =IFERROR(VLOOKUP($D47,'Master Sheet'!$B:$AA,5,FALSE),"") -> 018208046607 | K47: =IFERROR(VLOOKUP($D47,'Master Sheet'!$B:$AA,8,FALSE),"") -> 1493.955
D48: CAMNIACMC36A | G48: =IFERROR(VLOOKUP($D48,'Master Sheet'!$B:$AA,3,FALSE),"") -> MC-36A REMOTE CORD - D4/D4S/D800/E | I48: =IFERROR(VLOOKUP($D48,'Master Sheet'!$B:$AA,2,FALSE),"") -> VDR00801 | J48: =IFERROR(VLOOKUP($D48,'Master Sheet'!$B:$AA,5,FALSE),"") -> 018208270323 | K48: =IFERROR(VLOOKUP($D48,'Master Sheet'!$B:$AA,8,FALSE),"") -> 3914.955
...

Sheet Z8
C3: Format
D4: FX
C5: Megapixels
D6: 45.7 MP
C7: Continuous Shooting
D8: 20 FPS Raw
D9: 30 FPS JPEG
C10: ISO
D11: ISO 64–25600, ISO Expandable to 102,400
C13: Video
D14: 8K UHD 7,680 × 4,320 / 30p (progressive)
C16: Memory
D17: Dual card slots, Cfexpress/XQD & SD
C19: Monitor Size
D20: 3.2 Inch V/H Tilt Touch-LCD | G20: The ultimate hybrid camera.
C22: Order Code | G22: Details | I22: Product Code | J22: Barcode | K22: Dealer (Export)
D24: CAMNIILCZ8 | G24: =IFERROR(VLOOKUP($D24,'Master Sheet'!$B:$AA,3,FALSE),"") -> Nikon Z8 Mirrorless Digital Camera Body | I24: =IFERROR(VLOOKUP($D24,'Master Sheet'!$B:$AA,2,FALSE),"") -> VOA100AM | J24: =IFERROR(VLOOKUP($D24,'Master Sheet'!$B:$AA,5,FALSE),"") -> 4960759909985 | K24: =IFERROR(VLOOKUP($D24,'Master Sheet'!$B:$AA,8,FALSE),"") -> 66527.955
G25: =IFERROR(VLOOKUP($D25,'Master Sheet'!$B:$AA,3,FALSE),"") | I25: =IFERROR(VLOOKUP($D25,'Master Sheet'!$B:$AA,2,FALSE),"") | J25: =IFERROR(VLOOKUP($D25,'Master Sheet'!$B:$AA,5,FALSE),"") | K25: =IFERROR(VLOOKUP($D25,'Master Sheet'!$B:$AA,8,FALSE),"")
C26: Body Cap
D27: CAMNIACILCBFN1 | G27: =IFERROR(VLOOKUP($D27,'Master Sheet'!$B:$AA,3,FALSE),"") -> BF-N1 Body Cap (Z-Series) | I27: =IFERROR(VLOOKUP($D27,'Master Sheet'!$B:$AA,2,FALSE),"") -> VOD00101 | J27: =IFERROR(VLOOKUP($D27,'Master Sheet'!$B:$AA,5,FALSE),"") -> 4960759901002 | K27: =IFERROR(VLOOKUP($D27,'Master Sheet'!$B:$AA,8,FALSE),"") -> 116.955
C29: Lens Adapter
D30: CAMNIACILCFTZII | G30: =IFERROR(VLOOKUP($D30,'Master Sheet'!$B:$AA,3,FALSE),"") -> FTZ II Mount Adapter | I30: =IFERROR(VLOOKUP($D30,'Master Sheet'!$B:$AA,2,FALSE),"") -> JMA905DA | J30: =IFERROR(VLOOKUP($D30,'Master Sheet'!$B:$AA,5,FALSE),"") -> 018208042647 | K30: =IFERROR(VLOOKUP($D30,'Master Sheet'!$B:$AA,8,FALSE),"") -> 4049.955
G31: =IFERROR(VLOOKUP($D31,'Master Sheet'!$B:$AA,3,FALSE),"") | I31: =IFERROR(VLOOKUP($D31,'Master Sheet'!$B:$AA,2,FALSE),"") | J31: =IFERROR(VLOOKUP($D31,'Master Sheet'!$B:$AA,5,FALSE),"") | K31: =IFERROR(VLOOKUP($D31,'Master Sheet'!$B:$AA,8,FALSE),"")
C32: Lenses
G33: (See Mirrorless Lenses Pricelist Sheets) | I33: =IFERROR(VLOOKUP($D33,'Master Sheet'!$B:$AA,2,FALSE),"") | J33: =IFERROR(VLOOKUP($D33,'Master Sheet'!$B:$AA,5,FALSE),"") | K33: =IFERROR(VLOOKUP($D33,'Master Sheet'!$B:$AA,8,FALSE),"")
G34: =IFERROR(VLOOKUP($D34,'Master Sheet'!$B:$AA,3,FALSE),"") | I34: =IFERROR(VLOOKUP($D34,'Master Sheet'!$B:$AA,2,FALSE),"") | J34: =IFERROR(VLOOKUP($D34,'Master Sheet'!$B:$AA,5,FALSE),"") | K34: =IFERROR(VLOOKUP($D34,'Master Sheet'!$B:$AA,8,FALSE),"")
C35: Speedlights/Flashes
G36: (See Speedlight Pricelist Sheets) | I36: =IFERROR(VLOOKUP($D36,'Master Sheet'!$B:$AA,2,FALSE),"") | J36: =IFERROR(VLOOKUP($D36,'Master Sheet'!$B:$AA,5,FALSE),"") | K36: =IFERROR(VLOOKUP($D36,'Master Sheet'!$B:$AA,8,FALSE),"")
G37: =IFERROR(VLOOKUP($D37,'Master Sheet'!$B:$AA,3,FALSE),"") | I37: =IFERROR(VLOOKUP($D37,'Master Sheet'!$B:$AA,2,FALSE),"") | J37: =IFERROR(VLOOKUP($D37,'Master Sheet'!$B:$AA,5,FALSE),"") | K37: =IFERROR(VLOOKUP($D37,'Master Sheet'!$B:$AA,8,FALSE),"")
C38: Power Accessories
D39: CAMNIACILCMBN12 | G39: =IFERROR(VLOOKUP($D39,'Master Sheet'!$B:$AA,3,FALSE),"") -> Nikon MB-N12 battery pack for the Z8 | I39: =IFERROR(VLOOKUP($D39,'Master Sheet'!$B:$AA,2,FALSE),"") -> MB-N12 | J39: =IFERROR(VLOOKUP($D39,'Master Sheet'!$B:$AA,5,FALSE),"") -> 018208272273 | K39: =IFERROR(VLOOKUP($D39,'Master Sheet'!$B:$AA,8,FALSE),"") -> 8279.955
D40: CAMNIACENEL15C | G40: =IFERROR(VLOOKUP($D40,'Master Sheet'!$B:$AA,3,FALSE),"") -> EN-EL15C RECHARGEABLE LI-ION BATTERY | I40: =IFERROR(VLOOKUP($D40,'Master Sheet'!$B:$AA,2,FALSE),"") -> VFB12802 | J40: =IFERROR(VLOOKUP($D40,'Master Sheet'!$B:$AA,5,FALSE),"") -> 4960759904393 | K40: =IFERROR(VLOOKUP($D40,'Master Sheet'!$B:$AA,8,FALSE),"") -> 1439.955
D41: CAMNIACMH25A | G41: =IFERROR(VLOOKUP($D41,'Master Sheet'!$B:$AA,3,FALSE),"") -> MH-25A BATTERY CHARGER - EN-EL15 Battery | I41: =IFERROR(VLOOKUP($D41,'Master Sheet'!$B:$AA,2,FALSE),"") -> VEA016EA | J41: =IFERROR(VLOOKUP($D41,'Master Sheet'!$B:$AA,5,FALSE),"") -> 018208941704 | K41: =IFERROR(VLOOKUP($D41,'Master Sheet'!$B:$AA,8,FALSE),"") -> 1106.955
D42: CAMNIACEP5B | G42: =IFERROR(VLOOKUP($D42,'Master Sheet'!$B:$AA,3,FALSE),"") -> EP-5B POWER CONNECTOR - D7000/D7100/D600/D610/D800/E | I42: =IFERROR(VLOOKUP($D42,'Master Sheet'!$B:$AA,2,FALSE),"") -> VEB00901 | J42: =IFERROR(VLOOKUP($D42,'Master Sheet'!$B:$AA,5,FALSE),"") -> 018208270149 | K42: =IFERROR(VLOOKUP($D42,'Master Sheet'!$B:$AA,8,FALSE),"") -> 863.955
G43: =IFERROR(VLOOKUP($D43,'Master Sheet'!$B:$AA,3,FALSE),"") | I43: =IFERROR(VLOOKUP($D43,'Master Sheet'!$B:$AA,2,FALSE),"") | J43: =IFERROR(VLOOKUP($D43,'Master Sheet'!$B:$AA,5,FALSE),"") | K43: =IFERROR(VLOOKUP($D43,'Master Sheet'!$B:$AA,8,FALSE),"")
C44: Remotes & Releases
D45: CAMNIACILMCN10 | G45: =IFERROR(VLOOKUP($D45,'Master Sheet'!$B:$AA,3,FALSE),"") -> Nikon MC-N10 Remote Grip | I45: =IFERROR(VLOOKUP($D45,'Master Sheet'!$B:$AA,2,FALSE),"") -> VDR009AA | J45: =IFERROR(VLOOKUP($D45,'Master Sheet'!$B:$AA,5,FALSE),"") -> 018208272303 | K45: =IFERROR(VLOOKUP($D45,'Master Sheet'!$B:$AA,8,FALSE),"") -> 9629.955
D46: CAMNIACMC30A | G46: =IFERROR(VLOOKUP($D46,'Master Sheet'!$B:$AA,3,FALSE),"") -> MC-30A REMOTE CORD - D4/D4S/D800/E | I46: =IFERROR(VLOOKUP($D46,'Master Sheet'!$B:$AA,2,FALSE),"") -> VDR00601 | J46: =IFERROR(VLOOKUP($D46,'Master Sheet'!$B:$AA,5,FALSE),"") -> 018208046607 | K46: =IFERROR(VLOOKUP($D46,'Master Sheet'!$B:$AA,8,FALSE),"") -> 1493.955
D47: CAMNIACMC36A | G47: =IFERROR(VLOOKUP($D47,'Master Sheet'!$B:$AA,3,FALSE),"") -> MC-36A REMOTE CORD - D4/D4S/D800/E | I47: =IFERROR(VLOOKUP($D47,'Master Sheet'!$B:$AA,2,FALSE),"") -> VDR00801 | J47: =IFERROR(VLOOKUP($D47,'Master Sheet'!$B:$AA,5,FALSE),"") -> 018208270323 | K47: =IFERROR(VLOOKUP($D47,'Master Sheet'!$B:$AA,8,FALSE),"") -> 3914.955
D48: CAMNIACWRR11A | G48: =IFERROR(VLOOKUP($D48,'Master Sheet'!$B:$AA,3,FALSE),"") -> WR-R11A WIRELESS REMOTE CONTROLLER | I48: =IFERROR(VLOOKUP($D48,'Master Sheet'!$B:$AA,2,FALSE),"") -> VBJ005CG | J48: =IFERROR(VLOOKUP($D48,'Master Sheet'!$B:$AA,5,FALSE),"") -> 4960759905192 | K48: =IFERROR(VLOOKUP($D48,'Master Sheet'!$B:$AA,8,FALSE),"") -> 3365.955
...

Sheet Z7 II
C3: Format
D4: FX
C5: Megapixels
D6: 45.7 MP
C7: Continuous Shooting
D8: 10 FPS
C10: ISO
D11: ISO 64–25600, ISO Expandable to 102,400
C13: Video
D14: 4K UHD 3,840 x 2,160 / 60 fps
C16: Memory
D17: Dual card slots, Cfexpress/XQD & SD
C19: Monitor Size
D20: 3.2 Inch Tilt Touch-LCD | G20: Intensive details. Extraordinary results.
C22: Order Code | G22: Details | I22: Product Code | J22: Barcode | K22: Dealer (Export)
D24: CAMNIILCZ7II | G24: =IFERROR(VLOOKUP($D24,'Master Sheet'!$B:$AA,3,FALSE),"") -> Nikon Z7 II Mirrorless Digital Camera Body | I24: =IFERROR(VLOOKUP($D24,'Master Sheet'!$B:$AA,2,FALSE),"") -> VOA070AM | J24: =IFERROR(VLOOKUP($D24,'Master Sheet'!$B:$AA,5,FALSE),"") -> 4960759905734 | K24: =IFERROR(VLOOKUP($D24,'Master Sheet'!$B:$AA,8,FALSE),"") -> 58697.955
D25: CAMNIILCZ7IIK001 | G25: =IFERROR(VLOOKUP($D25,'Master Sheet'!$B:$AA,3,FALSE),"") -> Nikon Z7 II Mirrorless Digital Camera+NIKKOR Z 24-70mm f/4 S Lens | I25: =IFERROR(VLOOKUP($D25,'Master Sheet'!$B:$AA,2,FALSE),"") -> 0 | J25: =IFERROR(VLOOKUP($D25,'Master Sheet'!$B:$AA,5,FALSE),"") -> 6009658262246 | K25: =IFERROR(VLOOKUP($D25,'Master Sheet'!$B:$AA,8,FALSE),"") -> 69650.955
G26: =IFERROR(VLOOKUP($D26,'Master Sheet'!$B:$AA,3,FALSE),"") | I26: =IFERROR(VLOOKUP($D26,'Master Sheet'!$B:$AA,2,FALSE),"") | J26: =IFERROR(VLOOKUP($D26,'Master Sheet'!$B:$AA,5,FALSE),"") | K26: =IFERROR(VLOOKUP($D26,'Master Sheet'!$B:$AA,8,FALSE),"")
C27: Body Cap
D28: CAMNIACILCBFN1 | G28: =IFERROR(VLOOKUP($D28,'Master Sheet'!$B:$AA,3,FALSE),"") -> BF-N1 Body Cap (Z-Series) | I28: =IFERROR(VLOOKUP($D28,'Master Sheet'!$B:$AA,2,FALSE),"") -> VOD00101 | J28: =IFERROR(VLOOKUP($D28,'Master Sheet'!$B:$AA,5,FALSE),"") -> 4960759901002 | K28: =IFERROR(VLOOKUP($D28,'Master Sheet'!$B:$AA,8,FALSE),"") -> 116.955
C30: Lens Adapter
D31: CAMNIACILCFTZII | G31: =IFERROR(VLOOKUP($D31,'Master Sheet'!$B:$AA,3,FALSE),"") -> FTZ II Mount Adapter | I31: =IFERROR(VLOOKUP($D31,'Master Sheet'!$B:$AA,2,FALSE),"") -> JMA905DA | J31: =IFERROR(VLOOKUP($D31,'Master Sheet'!$B:$AA,5,FALSE),"") -> 018208042647 | K31: =IFERROR(VLOOKUP($D31,'Master Sheet'!$B:$AA,8,FALSE),"") -> 4049.955
G32: =IFERROR(VLOOKUP($D32,'Master Sheet'!$B:$AA,3,FALSE),"") | I32: =IFERROR(VLOOKUP($D32,'Master Sheet'!$B:$AA,2,FALSE),"") | J32: =IFERROR(VLOOKUP($D32,'Master Sheet'!$B:$AA,5,FALSE),"") | K32: =IFERROR(VLOOKUP($D32,'Master Sheet'!$B:$AA,8,FALSE),"")
C33: Lenses
G34: (See Mirrorless Lenses Pricelist Sheets) | I34: =IFERROR(VLOOKUP($D34,'Master Sheet'!$B:$AA,2,FALSE),"") | J34: =IFERROR(VLOOKUP($D34,'Master Sheet'!$B:$AA,5,FALSE),"") | K34: =IFERROR(VLOOKUP($D34,'Master Sheet'!$B:$AA,8,FALSE),"")
G35: =IFERROR(VLOOKUP($D35,'Master Sheet'!$B:$AA,3,FALSE),"") | I35: =IFERROR(VLOOKUP($D35,'Master Sheet'!$B:$AA,2,FALSE),"") | J35: =IFERROR(VLOOKUP($D35,'Master Sheet'!$B:$AA,5,FALSE),"") | K35: =IFERROR(VLOOKUP($D35,'Master Sheet'!$B:$AA,8,FALSE),"")
C36: Speedlights/Flashes
G37: (See Speedlight Pricelist Sheets) | I37: =IFERROR(VLOOKUP($D37,'Master Sheet'!$B:$AA,2,FALSE),"") | J37: =IFERROR(VLOOKUP($D37,'Master Sheet'!$B:$AA,5,FALSE),"") | K37: =IFERROR(VLOOKUP($D37,'Master Sheet'!$B:$AA,8,FALSE),"")
G38: =IFERROR(VLOOKUP($D38,'Master Sheet'!$B:$AA,3,FALSE),"") | I38: =IFERROR(VLOOKUP($D38,'Master Sheet'!$B:$AA,2,FALSE),"") | J38: =IFERROR(VLOOKUP($D38,'Master Sheet'!$B:$AA,5,FALSE),"") | K38: =IFERROR(VLOOKUP($D38,'Master Sheet'!$B:$AA,8,FALSE),"")
C39: Power Accessories
D40: CAMNIACEH5D | G40: =IFERROR(VLOOKUP($D40,'Master Sheet'!$B:$AA,3,FALSE),"") -> AC Adapter EH-5d | I40: =IFERROR(VLOOKUP($D40,'Master Sheet'!$B:$AA,2,FALSE),"") -> VEB033EA | J40: =IFERROR(VLOOKUP($D40,'Master Sheet'!$B:$AA,5,FALSE),"") -> 4960759903143 | K40: =IFERROR(VLOOKUP($D40,'Master Sheet'!$B:$AA,8,FALSE),"") -> 1736.955
D41: CAMNIACILCEH7P | G41: =IFERROR(VLOOKUP($D41,'Master Sheet'!$B:$AA,3,FALSE),"") -> Charging AC Adapter EH-7P | I41: =IFERROR(VLOOKUP($D41,'Master Sheet'!$B:$AA,2,FALSE),"") -> VEB029BA | J41: =IFERROR(VLOOKUP($D41,'Master Sheet'!$B:$AA,5,FALSE),"") -> 4960759901958 | K41: =IFERROR(VLOOKUP($D41,'Master Sheet'!$B:$AA,8,FALSE),"") -> 917.955
D42: CAMNIACENEL15C | G42: =IFERROR(VLOOKUP($D42,'Master Sheet'!$B:$AA,3,FALSE),"") -> EN-EL15C RECHARGEABLE LI-ION BATTERY | I42: =IFERROR(VLOOKUP($D42,'Master Sheet'!$B:$AA,2,FALSE),"") -> VFB12802 | J42: =IFERROR(VLOOKUP($D42,'Master Sheet'!$B:$AA,5,FALSE),"") -> 4960759904393 | K42: =IFERROR(VLOOKUP($D42,'Master Sheet'!$B:$AA,8,FALSE),"") -> 1439.955
D43: CAMNIACEP5B | G43: =IFERROR(VLOOKUP($D43,'Master Sheet'!$B:$AA,3,FALSE),"") -> EP-5B POWER CONNECTOR - D7000/D7100/D600/D610/D800/E | I43: =IFERROR(VLOOKUP($D43,'Master Sheet'!$B:$AA,2,FALSE),"") -> VEB00901 | J43: =IFERROR(VLOOKUP($D43,'Master Sheet'!$B:$AA,5,FALSE),"") -> 018208270149 | K43: =IFERROR(VLOOKUP($D43,'Master Sheet'!$B:$AA,8,FALSE),"") -> 863.955
D44: CAMNIACILCMBN10 | G44: =IFERROR(VLOOKUP($D44,'Master Sheet'!$B:$AA,3,FALSE),"") -> Nikon MB-N10 battery pack for the Z6/Z7 | I44: =IFERROR(VLOOKUP($D44,'Master Sheet'!$B:$AA,2,FALSE),"") -> VFC00801 | J44: =IFERROR(VLOOKUP($D44,'Master Sheet'!$B:$AA,5,FALSE),"") -> 018208272044 | K44: =IFERROR(VLOOKUP($D44,'Master Sheet'!$B:$AA,8,FALSE),"") -> 5039.955
D45: CAMNIACILCMBN11 | G45: =IFERROR(VLOOKUP($D45,'Master Sheet'!$B:$AA,3,FALSE),"") -> Nikon MB-N11 battery pack for the Z6 II/Z7 II | I45: =IFERROR(VLOOKUP($D45,'Master Sheet'!$B:$AA,2,FALSE),"") -> VFC00901 | J45: =IFERROR(VLOOKUP($D45,'Master Sheet'!$B:$AA,5,FALSE),"") -> 018208272150 | K45: =IFERROR(VLOOKUP($D45,'Master Sheet'!$B:$AA,8,FALSE),"") -> 7559.955
D46: CAMNIACMH25A | G46: =IFERROR(VLOOKUP($D46,'Master Sheet'!$B:$AA,3,FALSE),"") -> MH-25A BATTERY CHARGER - EN-EL15 Battery | I46: =IFERROR(VLOOKUP($D46,'Master Sheet'!$B:$AA,2,FALSE),"") -> VEA016EA | J46: =IFERROR(VLOOKUP($D46,'Master Sheet'!$B:$AA,5,FALSE),"") -> 018208941704 | K46: =IFERROR(VLOOKUP($D46,'Master Sheet'!$B:$AA,8,FALSE),"") -> 1106.955
G47: =IFERROR(VLOOKUP($D47,'Master Sheet'!$B:$AA,3,FALSE),"") | I47: =IFERROR(VLOOKUP($D47,'Master Sheet'!$B:$AA,2,FALSE),"") | J47: =IFERROR(VLOOKUP($D47,'Master Sheet'!$B:$AA,5,FALSE),"") | K47: =IFERROR(VLOOKUP($D47,'Master Sheet'!$B:$AA,8,FALSE),"")
C48: Remotes & Releases
D49: CAMNIACMCDC3 | G49: =IFERROR(VLOOKUP($D49,'Master Sheet'!$B:$AA,3,FALSE),"") -> Nikon MC-DC3 Remote Release Cord | I49: =IFERROR(VLOOKUP($D49,'Master Sheet'!$B:$AA,2,FALSE),"") -> VDR01001 | J49: =IFERROR(VLOOKUP($D49,'Master Sheet'!$B:$AA,5,FALSE),"") -> No Barcode | K49: =IFERROR(VLOOKUP($D49,'Master Sheet'!$B:$AA,8,FALSE),"") -> 584.955
...

Sheet Z6 III
C3: Format
D4: FX
C5: Megapixels
D6: 24.5 MP
C7: Continuous Shooting
D8: 14 FPS
C10: ISO
D11: ISO 100-64,000, ISO Expandable to 204,800
C13: Video
D14: 4K UHD 3,840 x 2,160 / 30 fps
C16: Memory
D17: Dual CFexpress Type B card slots
C19: Monitor Size
D20: 3.2 Inch Diagonal Touch-LCD | G20: More powerful. More speed. More possibilities
C22: Order Code | G22: Details | I22: Product Code | J22: Barcode | K22: Dealer (Export)
D24: CAMNIILCZ6III | G24: =IFERROR(VLOOKUP($D24,'Master Sheet'!$B:$AA,3,FALSE),"") -> Nikon Z6 III Mirrorless Digital Camera Body | I24: =IFERROR(VLOOKUP($D24,'Master Sheet'!$B:$AA,2,FALSE),"") -> VOA130AM | J24: =IFERROR(VLOOKUP($D24,'Master Sheet'!$B:$AA,5,FALSE),"") -> 4960759916204 | K24: =IFERROR(VLOOKUP($D24,'Master Sheet'!$B:$AA,8,FALSE),"") -> 43046.955
G25: =IFERROR(VLOOKUP($D25,'Master Sheet'!$B:$AA,3,FALSE),"") | I25: =IFERROR(VLOOKUP($D25,'Master Sheet'!$B:$AA,2,FALSE),"") | J25: =IFERROR(VLOOKUP($D25,'Master Sheet'!$B:$AA,5,FALSE),"") | K25: =IFERROR(VLOOKUP($D25,'Master Sheet'!$B:$AA,8,FALSE),"")
C26: Body Cap
D27: CAMNIACILCBFN1 | G27: =IFERROR(VLOOKUP($D27,'Master Sheet'!$B:$AA,3,FALSE),"") -> BF-N1 Body Cap (Z-Series) | I27: =IFERROR(VLOOKUP($D27,'Master Sheet'!$B:$AA,2,FALSE),"") -> VOD00101 | J27: =IFERROR(VLOOKUP($D27,'Master Sheet'!$B:$AA,5,FALSE),"") -> 4960759901002 | K27: =IFERROR(VLOOKUP($D27,'Master Sheet'!$B:$AA,8,FALSE),"") -> 116.955
C29: Lens Adapter
D30: CAMNIACILCFTZII | G30: =IFERROR(VLOOKUP($D30,'Master Sheet'!$B:$AA,3,FALSE),"") -> FTZ II Mount Adapter | I30: =IFERROR(VLOOKUP($D30,'Master Sheet'!$B:$AA,2,FALSE),"") -> JMA905DA | J30: =IFERROR(VLOOKUP($D30,'Master Sheet'!$B:$AA,5,FALSE),"") -> 018208042647 | K30: =IFERROR(VLOOKUP($D30,'Master Sheet'!$B:$AA,8,FALSE),"") -> 4049.955
G31: =IFERROR(VLOOKUP($D31,'Master Sheet'!$B:$AA,3,FALSE),"") | I31: =IFERROR(VLOOKUP($D31,'Master Sheet'!$B:$AA,2,FALSE),"") | J31: =IFERROR(VLOOKUP($D31,'Master Sheet'!$B:$AA,5,FALSE),"") | K31: =IFERROR(VLOOKUP($D31,'Master Sheet'!$B:$AA,8,FALSE),"")
C32: Lenses
G33: (See Mirrorless Lenses Pricelist Sheets) | I33: =IFERROR(VLOOKUP($D33,'Master Sheet'!$B:$AA,2,FALSE),"") | J33: =IFERROR(VLOOKUP($D33,'Master Sheet'!$B:$AA,5,FALSE),"") | K33: =IFERROR(VLOOKUP($D33,'Master Sheet'!$B:$AA,8,FALSE),"")
G34: =IFERROR(VLOOKUP($D34,'Master Sheet'!$B:$AA,3,FALSE),"") | I34: =IFERROR(VLOOKUP($D34,'Master Sheet'!$B:$AA,2,FALSE),"") | J34: =IFERROR(VLOOKUP($D34,'Master Sheet'!$B:$AA,5,FALSE),"") | K34: =IFERROR(VLOOKUP($D34,'Master Sheet'!$B:$AA,8,FALSE),"")
C35: Speedlights/Flashes
G36: (See Speedlight Pricelist Sheets) | I36: =IFERROR(VLOOKUP($D36,'Master Sheet'!$B:$AA,2,FALSE),"") | J36: =IFERROR(VLOOKUP($D36,'Master Sheet'!$B:$AA,5,FALSE),"") | K36: =IFERROR(VLOOKUP($D36,'Master Sheet'!$B:$AA,8,FALSE),"")
G37: =IFERROR(VLOOKUP($D37,'Master Sheet'!$B:$AA,3,FALSE),"") | I37: =IFERROR(VLOOKUP($D37,'Master Sheet'!$B:$AA,2,FALSE),"") | J37: =IFERROR(VLOOKUP($D37,'Master Sheet'!$B:$AA,5,FALSE),"") | K37: =IFERROR(VLOOKUP($D37,'Master Sheet'!$B:$AA,8,FALSE),"")
C38: Power Accessories
D39: CAMNIACEH5D | G39: =IFERROR(VLOOKUP($D39,'Master Sheet'!$B:$AA,3,FALSE),"") -> AC Adapter EH-5d | I39: =IFERROR(VLOOKUP($D39,'Master Sheet'!$B:$AA,2,FALSE),"") -> VEB033EA | J39: =IFERROR(VLOOKUP($D39,'Master Sheet'!$B:$AA,5,FALSE),"") -> 4960759903143 | K39: =IFERROR(VLOOKUP($D39,'Master Sheet'!$B:$AA,8,FALSE),"") -> 1736.955
D40: CAMNIACILCEH7P | G40: =IFERROR(VLOOKUP($D40,'Master Sheet'!$B:$AA,3,FALSE),"") -> Charging AC Adapter EH-7P | I40: =IFERROR(VLOOKUP($D40,'Master Sheet'!$B:$AA,2,FALSE),"") -> VEB029BA | J40: =IFERROR(VLOOKUP($D40,'Master Sheet'!$B:$AA,5,FALSE),"") -> 4960759901958 | K40: =IFERROR(VLOOKUP($D40,'Master Sheet'!$B:$AA,8,FALSE),"") -> 917.955
D41: CAMNIACENEL15C | G41: =IFERROR(VLOOKUP($D41,'Master Sheet'!$B:$AA,3,FALSE),"") -> EN-EL15C RECHARGEABLE LI-ION BATTERY | I41: =IFERROR(VLOOKUP($D41,'Master Sheet'!$B:$AA,2,FALSE),"") -> VFB12802 | J41: =IFERROR(VLOOKUP($D41,'Master Sheet'!$B:$AA,5,FALSE),"") -> 4960759904393 | K41: =IFERROR(VLOOKUP($D41,'Master Sheet'!$B:$AA,8,FALSE),"") -> 1439.955
D42: CAMNIACEP5B | G42: =IFERROR(VLOOKUP($D42,'Master Sheet'!$B:$AA,3,FALSE),"") -> EP-5B POWER CONNECTOR - D7000/D7100/D600/D610/D800/E | I42: =IFERROR(VLOOKUP($D42,'Master Sheet'!$B:$AA,2,FALSE),"") -> VEB00901 | J42: =IFERROR(VLOOKUP($D42,'Master Sheet'!$B:$AA,5,FALSE),"") -> 018208270149 | K42: =IFERROR(VLOOKUP($D42,'Master Sheet'!$B:$AA,8,FALSE),"") -> 863.955
D43: CAMNIACILCMBN14 | G43: =IFERROR(VLOOKUP($D43,'Master Sheet'!$B:$AA,3,FALSE),"") -> Nikon MB-N14 Power battery pack for the Z6III | I43: =IFERROR(VLOOKUP($D43,'Master Sheet'!$B:$AA,2,FALSE),"") -> VFC01101 | J43: =IFERROR(VLOOKUP($D43,'Master Sheet'!$B:$AA,5,FALSE),"") -> 018208272402 | K43: =IFERROR(VLOOKUP($D43,'Master Sheet'!$B:$AA,8,FALSE),"") -> 8279.955
D44: CAMNIACMH25A | G44: =IFERROR(VLOOKUP($D44,'Master Sheet'!$B:$AA,3,FALSE),"") -> MH-25A BATTERY CHARGER - EN-EL15 Battery | I44: =IFERROR(VLOOKUP($D44,'Master Sheet'!$B:$AA,2,FALSE),"") -> VEA016EA | J44: =IFERROR(VLOOKUP($D44,'Master Sheet'!$B:$AA,5,FALSE),"") -> 018208941704 | K44: =IFERROR(VLOOKUP($D44,'Master Sheet'!$B:$AA,8,FALSE),"") -> 1106.955
G45: =IFERROR(VLOOKUP($D45,'Master Sheet'!$B:$AA,3,FALSE),"") | I45: =IFERROR(VLOOKUP($D45,'Master Sheet'!$B:$AA,2,FALSE),"") | J45: =IFERROR(VLOOKUP($D45,'Master Sheet'!$B:$AA,5,FALSE),"") | K45: =IFERROR(VLOOKUP($D45,'Master Sheet'!$B:$AA,8,FALSE),"")
C46: Remotes & Releases
D47: CAMNIACILMCN10 | G47: =IFERROR(VLOOKUP($D47,'Master Sheet'!$B:$AA,3,FALSE),"") -> Nikon MC-N10 Remote Grip | I47: =IFERROR(VLOOKUP($D47,'Master Sheet'!$B:$AA,2,FALSE),"") -> VDR009AA | J47: =IFERROR(VLOOKUP($D47,'Master Sheet'!$B:$AA,5,FALSE),"") -> 018208272303 | K47: =IFERROR(VLOOKUP($D47,'Master Sheet'!$B:$AA,8,FALSE),"") -> 9629.955
D48: CAMNIACMCDC3 | G48: =IFERROR(VLOOKUP($D48,'Master Sheet'!$B:$AA,3,FALSE),"") -> Nikon MC-DC3 Remote Release Cord | I48: =IFERROR(VLOOKUP($D48,'Master Sheet'!$B:$AA,2,FALSE),"") -> VDR01001 | J48: =IFERROR(VLOOKUP($D48,'Master Sheet'!$B:$AA,5,FALSE),"") -> No Barcode | K48: =IFERROR(VLOOKUP($D48,'Master Sheet'!$B:$AA,8,FALSE),"") -> 584.955
D49: CAMNIACMLL7 | G49: =IFERROR(VLOOKUP($D49,'Master Sheet'!$B:$AA,3,FALSE),"") -> ML-L7 REMOTE CONTROL | I49: =IFERROR(VLOOKUP($D49,'Master Sheet'!$B:$AA,2,FALSE),"") -> VAJ57201 | J49: =IFERROR(VLOOKUP($D49,'Master Sheet'!$B:$AA,5,FALSE),"") -> 018208259526 | K49: =IFERROR(VLOOKUP($D49,'Master Sheet'!$B:$AA,8,FALSE),"") -> 800.955
...

Sheet Z6 II
C3: Format
D4: FX
C5: Megapixels
D6: 24.5 MP
C7: Continuous Shooting
D8: 14 FPS
C10: ISO
D11: ISO 100-51,200, ISO Expandable to 204,800
C13: Video
D14: 4K UHD 3,840 x 2,160 / 30 fps
C16: Memory
D17: Dual CFexpress Type B card slots
C19: Monitor Size
D20: 3.2 Inch Tilt Touch-LCD | G20: More powerful. More speed. More possibilities
C22: Order Code | G22: Details | I22: Product Code | J22: Barcode | K22: Dealer (Export)
D24: CAMNIILCZ6II | G24: =IFERROR(VLOOKUP($D24,'Master Sheet'!$B:$AA,3,FALSE),"") -> Nikon Z6 II Mirrorless Digital Camera Body | I24: =IFERROR(VLOOKUP($D24,'Master Sheet'!$B:$AA,2,FALSE),"") -> VOA060AM | J24: =IFERROR(VLOOKUP($D24,'Master Sheet'!$B:$AA,5,FALSE),"") -> 4960759905949 | K24: =IFERROR(VLOOKUP($D24,'Master Sheet'!$B:$AA,8,FALSE),"") -> 39131.955
D25: CAMNIILCZ6IIK001 | G25: =IFERROR(VLOOKUP($D25,'Master Sheet'!$B:$AA,3,FALSE),"") -> Nikon Z6 II Mirrorless Digital Camera+NIKKOR Z 24-70mm f/4 S Lens | I25: =IFERROR(VLOOKUP($D25,'Master Sheet'!$B:$AA,2,FALSE),"") -> 0 | J25: =IFERROR(VLOOKUP($D25,'Master Sheet'!$B:$AA,5,FALSE),"") -> 6009658262215 | K25: =IFERROR(VLOOKUP($D25,'Master Sheet'!$B:$AA,8,FALSE),"") -> 50084.955
G26: =IFERROR(VLOOKUP($D26,'Master Sheet'!$B:$AA,3,FALSE),"") | I26: =IFERROR(VLOOKUP($D26,'Master Sheet'!$B:$AA,2,FALSE),"") | J26: =IFERROR(VLOOKUP($D26,'Master Sheet'!$B:$AA,5,FALSE),"") | K26: =IFERROR(VLOOKUP($D26,'Master Sheet'!$B:$AA,8,FALSE),"")
C27: Body Cap
D28: CAMNIACILCBFN1 | G28: =IFERROR(VLOOKUP($D28,'Master Sheet'!$B:$AA,3,FALSE),"") -> BF-N1 Body Cap (Z-Series) | I28: =IFERROR(VLOOKUP($D28,'Master Sheet'!$B:$AA,2,FALSE),"") -> VOD00101 | J28: =IFERROR(VLOOKUP($D28,'Master Sheet'!$B:$AA,5,FALSE),"") -> 4960759901002 | K28: =IFERROR(VLOOKUP($D28,'Master Sheet'!$B:$AA,8,FALSE),"") -> 116.955
C30: Lens Adapter
D31: CAMNIACILCFTZII | G31: =IFERROR(VLOOKUP($D31,'Master Sheet'!$B:$AA,3,FALSE),"") -> FTZ II Mount Adapter | I31: =IFERROR(VLOOKUP($D31,'Master Sheet'!$B:$AA,2,FALSE),"") -> JMA905DA | J31: =IFERROR(VLOOKUP($D31,'Master Sheet'!$B:$AA,5,FALSE),"") -> 018208042647 | K31: =IFERROR(VLOOKUP($D31,'Master Sheet'!$B:$AA,8,FALSE),"") -> 4049.955
G32: =IFERROR(VLOOKUP($D32,'Master Sheet'!$B:$AA,3,FALSE),"") | I32: =IFERROR(VLOOKUP($D32,'Master Sheet'!$B:$AA,2,FALSE),"") | J32: =IFERROR(VLOOKUP($D32,'Master Sheet'!$B:$AA,5,FALSE),"") | K32: =IFERROR(VLOOKUP($D32,'Master Sheet'!$B:$AA,8,FALSE),"")
C33: Lenses
G34: (See Mirrorless Lenses Pricelist Sheets) | I34: =IFERROR(VLOOKUP($D34,'Master Sheet'!$B:$AA,2,FALSE),"") | J34: =IFERROR(VLOOKUP($D34,'Master Sheet'!$B:$AA,5,FALSE),"") | K34: =IFERROR(VLOOKUP($D34,'Master Sheet'!$B:$AA,8,FALSE),"")
G35: =IFERROR(VLOOKUP($D35,'Master Sheet'!$B:$AA,3,FALSE),"") | I35: =IFERROR(VLOOKUP($D35,'Master Sheet'!$B:$AA,2,FALSE),"") | J35: =IFERROR(VLOOKUP($D35,'Master Sheet'!$B:$AA,5,FALSE),"") | K35: =IFERROR(VLOOKUP($D35,'Master Sheet'!$B:$AA,8,FALSE),"")
C36: Speedlights/Flashes
G37: (See Speedlight Pricelist Sheets) | I37: =IFERROR(VLOOKUP($D37,'Master Sheet'!$B:$AA,2,FALSE),"") | J37: =IFERROR(VLOOKUP($D37,'Master Sheet'!$B:$AA,5,FALSE),"") | K37: =IFERROR(VLOOKUP($D37,'Master Sheet'!$B:$AA,8,FALSE),"")
G38: =IFERROR(VLOOKUP($D38,'Master Sheet'!$B:$AA,3,FALSE),"") | I38: =IFERROR(VLOOKUP($D38,'Master Sheet'!$B:$AA,2,FALSE),"") | J38: =IFERROR(VLOOKUP($D38,'Master Sheet'!$B:$AA,5,FALSE),"") | K38: =IFERROR(VLOOKUP($D38,'Master Sheet'!$B:$AA,8,FALSE),"")
C39: Power Accessories
D40: CAMNIACEH5D | G40: =IFERROR(VLOOKUP($D40,'Master Sheet'!$B:$AA,3,FALSE),"") -> AC Adapter EH-5d | I40: =IFERROR(VLOOKUP($D40,'Master Sheet'!$B:$AA,2,FALSE),"") -> VEB033EA | J40: =IFERROR(VLOOKUP($D40,'Master Sheet'!$B:$AA,5,FALSE),"") -> 4960759903143 | K40: =IFERROR(VLOOKUP($D40,'Master Sheet'!$B:$AA,8,FALSE),"") -> 1736.955
D41: CAMNIACILCEH7P | G41: =IFERROR(VLOOKUP($D41,'Master Sheet'!$B:$AA,3,FALSE),"") -> Charging AC Adapter EH-7P | I41: =IFERROR(VLOOKUP($D41,'Master Sheet'!$B:$AA,2,FALSE),"") -> VEB029BA | J41: =IFERROR(VLOOKUP($D41,'Master Sheet'!$B:$AA,5,FALSE),"") -> 4960759901958 | K41: =IFERROR(VLOOKUP($D41,'Master Sheet'!$B:$AA,8,FALSE),"") -> 917.955
D42: CAMNIACENEL15C | G42: =IFERROR(VLOOKUP($D42,'Master Sheet'!$B:$AA,3,FALSE),"") -> EN-EL15C RECHARGEABLE LI-ION BATTERY | I42: =IFERROR(VLOOKUP($D42,'Master Sheet'!$B:$AA,2,FALSE),"") -> VFB12802 | J42: =IFERROR(VLOOKUP($D42,'Master Sheet'!$B:$AA,5,FALSE),"") -> 4960759904393 | K42: =IFERROR(VLOOKUP($D42,'Master Sheet'!$B:$AA,8,FALSE),"") -> 1439.955
D43: CAMNIACEP5B | G43: =IFERROR(VLOOKUP($D43,'Master Sheet'!$B:$AA,3,FALSE),"") -> EP-5B POWER CONNECTOR - D7000/D7100/D600/D610/D800/E | I43: =IFERROR(VLOOKUP($D43,'Master Sheet'!$B:$AA,2,FALSE),"") -> VEB00901 | J43: =IFERROR(VLOOKUP($D43,'Master Sheet'!$B:$AA,5,FALSE),"") -> 018208270149 | K43: =IFERROR(VLOOKUP($D43,'Master Sheet'!$B:$AA,8,FALSE),"") -> 863.955
D44: CAMNIACILCMBN10 | G44: =IFERROR(VLOOKUP($D44,'Master Sheet'!$B:$AA,3,FALSE),"") -> Nikon MB-N10 battery pack for the Z6/Z7 | I44: =IFERROR(VLOOKUP($D44,'Master Sheet'!$B:$AA,2,FALSE),"") -> VFC00801 | J44: =IFERROR(VLOOKUP($D44,'Master Sheet'!$B:$AA,5,FALSE),"") -> 018208272044 | K44: =IFERROR(VLOOKUP($D44,'Master Sheet'!$B:$AA,8,FALSE),"") -> 5039.955
D45: CAMNIACILCMBN11 | G45: =IFERROR(VLOOKUP($D45,'Master Sheet'!$B:$AA,3,FALSE),"") -> Nikon MB-N11 battery pack for the Z6 II/Z7 II | I45: =IFERROR(VLOOKUP($D45,'Master Sheet'!$B:$AA,2,FALSE),"") -> VFC00901 | J45: =IFERROR(VLOOKUP($D45,'Master Sheet'!$B:$AA,5,FALSE),"") -> 018208272150 | K45: =IFERROR(VLOOKUP($D45,'Master Sheet'!$B:$AA,8,FALSE),"") -> 7559.955
D46: CAMNIACMH25A | G46: =IFERROR(VLOOKUP($D46,'Master Sheet'!$B:$AA,3,FALSE),"") -> MH-25A BATTERY CHARGER - EN-EL15 Battery | I46: =IFERROR(VLOOKUP($D46,'Master Sheet'!$B:$AA,2,FALSE),"") -> VEA016EA | J46: =IFERROR(VLOOKUP($D46,'Master Sheet'!$B:$AA,5,FALSE),"") -> 018208941704 | K46: =IFERROR(VLOOKUP($D46,'Master Sheet'!$B:$AA,8,FALSE),"") -> 1106.955
G47: =IFERROR(VLOOKUP($D47,'Master Sheet'!$B:$AA,3,FALSE),"") | I47: =IFERROR(VLOOKUP($D47,'Master Sheet'!$B:$AA,2,FALSE),"") | J47: =IFERROR(VLOOKUP($D47,'Master Sheet'!$B:$AA,5,FALSE),"") | K47: =IFERROR(VLOOKUP($D47,'Master Sheet'!$B:$AA,8,FALSE),"")
C48: Remotes & Releases
D49: CAMNIACMCDC3 | G49: =IFERROR(VLOOKUP($D49,'Master Sheet'!$B:$AA,3,FALSE),"") -> Nikon MC-DC3 Remote Release Cord | I49: =IFERROR(VLOOKUP($D49,'Master Sheet'!$B:$AA,2,FALSE),"") -> VDR01001 | J49: =IFERROR(VLOOKUP($D49,'Master Sheet'!$B:$AA,5,FALSE),"") -> No Barcode | K49: =IFERROR(VLOOKUP($D49,'Master Sheet'!$B:$AA,8,FALSE),"") -> 584.955
...

Sheet Z5
C3: Format
D4: FX
C5: Megapixels
D6: 24.3 MP
C7: Continuous Shooting
D8: 4.5 FPS
C10: ISO
D11: 100 to 51200. ISO Expandable to 102,400
C13: Video
D14: 4K/30p and 1080/120p video
C16: Memory
D17: Dual SD UHS-I/SDHC/SDXC
C19: Monitor Size
D20: 3.2 Inch Tilt Touch-LCD | G20: Compact yet powerful. Simple yet sophisticated.
C22: Order Code | G22: Details | I22: Product Code | J22: Barcode | K22: Dealer (Export)
D24: CAMNIILCZ5 | G24: =IFERROR(VLOOKUP($D24,'Master Sheet'!$B:$AA,3,FALSE),"") -> Nikon Z5 Mirrorless Digital Camera (Body Only) | I24: =IFERROR(VLOOKUP($D24,'Master Sheet'!$B:$AA,2,FALSE),"") -> VOA040AM | J24: =IFERROR(VLOOKUP($D24,'Master Sheet'!$B:$AA,5,FALSE),"") -> 4960759912596 | K24: =IFERROR(VLOOKUP($D24,'Master Sheet'!$B:$AA,8,FALSE),"") -> 24263.955
D25: CAMNIILCZ5K001 | G25: =IFERROR(VLOOKUP($D25,'Master Sheet'!$B:$AA,3,FALSE),"") -> Nikon Z5 Mirrorless Digital Camera+Z 24-50mm f3.5-6.3 Lens | I25: =IFERROR(VLOOKUP($D25,'Master Sheet'!$B:$AA,2,FALSE),"") -> 0 | J25: =IFERROR(VLOOKUP($D25,'Master Sheet'!$B:$AA,5,FALSE),"") -> 6009658262048 | K25: =IFERROR(VLOOKUP($D25,'Master Sheet'!$B:$AA,8,FALSE),"") -> 29744.955
G26: =IFERROR(VLOOKUP($D26,'Master Sheet'!$B:$AA,3,FALSE),"") | I26: =IFERROR(VLOOKUP($D26,'Master Sheet'!$B:$AA,2,FALSE),"") | J26: =IFERROR(VLOOKUP($D26,'Master Sheet'!$B:$AA,5,FALSE),"") | K26: =IFERROR(VLOOKUP($D26,'Master Sheet'!$B:$AA,8,FALSE),"")
C27: Body Cap
D28: CAMNIACILCBFN1 | G28: =IFERROR(VLOOKUP($D28,'Master Sheet'!$B:$AA,3,FALSE),"") -> BF-N1 Body Cap (Z-Series) | I28: =IFERROR(VLOOKUP($D28,'Master Sheet'!$B:$AA,2,FALSE),"") -> VOD00101 | J28: =IFERROR(VLOOKUP($D28,'Master Sheet'!$B:$AA,5,FALSE),"") -> 4960759901002 | K28: =IFERROR(VLOOKUP($D28,'Master Sheet'!$B:$AA,8,FALSE),"") -> 116.955
C30: Lens Adapter
D31: CAMNIACILCFTZII | G31: =IFERROR(VLOOKUP($D31,'Master Sheet'!$B:$AA,3,FALSE),"") -> FTZ II Mount Adapter | I31: =IFERROR(VLOOKUP($D31,'Master Sheet'!$B:$AA,2,FALSE),"") -> JMA905DA | J31: =IFERROR(VLOOKUP($D31,'Master Sheet'!$B:$AA,5,FALSE),"") -> 018208042647 | K31: =IFERROR(VLOOKUP($D31,'Master Sheet'!$B:$AA,8,FALSE),"") -> 4049.955
G32: =IFERROR(VLOOKUP($D32,'Master Sheet'!$B:$AA,3,FALSE),"") | I32: =IFERROR(VLOOKUP($D32,'Master Sheet'!$B:$AA,2,FALSE),"") | J32: =IFERROR(VLOOKUP($D32,'Master Sheet'!$B:$AA,5,FALSE),"") | K32: =IFERROR(VLOOKUP($D32,'Master Sheet'!$B:$AA,8,FALSE),"")
C33: Lenses
G34: (See Mirrorless Lenses Pricelist Sheets) | I34: =IFERROR(VLOOKUP($D34,'Master Sheet'!$B:$AA,2,FALSE),"") | J34: =IFERROR(VLOOKUP($D34,'Master Sheet'!$B:$AA,5,FALSE),"") | K34: =IFERROR(VLOOKUP($D34,'Master Sheet'!$B:$AA,8,FALSE),"")
G35: =IFERROR(VLOOKUP($D35,'Master Sheet'!$B:$AA,3,FALSE),"") | I35: =IFERROR(VLOOKUP($D35,'Master Sheet'!$B:$AA,2,FALSE),"") | J35: =IFERROR(VLOOKUP($D35,'Master Sheet'!$B:$AA,5,FALSE),"") | K35: =IFERROR(VLOOKUP($D35,'Master Sheet'!$B:$AA,8,FALSE),"")
C36: Speedlights/Flashes
G37: (See Speedlight Pricelist Sheets) | I37: =IFERROR(VLOOKUP($D37,'Master Sheet'!$B:$AA,2,FALSE),"") | J37: =IFERROR(VLOOKUP($D37,'Master Sheet'!$B:$AA,5,FALSE),"") | K37: =IFERROR(VLOOKUP($D37,'Master Sheet'!$B:$AA,8,FALSE),"")
G38: =IFERROR(VLOOKUP($D38,'Master Sheet'!$B:$AA,3,FALSE),"") | I38: =IFERROR(VLOOKUP($D38,'Master Sheet'!$B:$AA,2,FALSE),"") | J38: =IFERROR(VLOOKUP($D38,'Master Sheet'!$B:$AA,5,FALSE),"") | K38: =IFERROR(VLOOKUP($D38,'Master Sheet'!$B:$AA,8,FALSE),"")
C39: Power Accessories
D40: CAMNIACEH5D | G40: =IFERROR(VLOOKUP($D40,'Master Sheet'!$B:$AA,3,FALSE),"") -> AC Adapter EH-5d | I40: =IFERROR(VLOOKUP($D40,'Master Sheet'!$B:$AA,2,FALSE),"") -> VEB033EA | J40: =IFERROR(VLOOKUP($D40,'Master Sheet'!$B:$AA,5,FALSE),"") -> 4960759903143 | K40: =IFERROR(VLOOKUP($D40,'Master Sheet'!$B:$AA,8,FALSE),"") -> 1736.955
D41: CAMNIACILCEH7P | G41: =IFERROR(VLOOKUP($D41,'Master Sheet'!$B:$AA,3,FALSE),"") -> Charging AC Adapter EH-7P | I41: =IFERROR(VLOOKUP($D41,'Master Sheet'!$B:$AA,2,FALSE),"") -> VEB029BA | J41: =IFERROR(VLOOKUP($D41,'Master Sheet'!$B:$AA,5,FALSE),"") -> 4960759901958 | K41: =IFERROR(VLOOKUP($D41,'Master Sheet'!$B:$AA,8,FALSE),"") -> 917.955
D42: CAMNIACENEL15C | G42: =IFERROR(VLOOKUP($D42,'Master Sheet'!$B:$AA,3,FALSE),"") -> EN-EL15C RECHARGEABLE LI-ION BATTERY | I42: =IFERROR(VLOOKUP($D42,'Master Sheet'!$B:$AA,2,FALSE),"") -> VFB12802 | J42: =IFERROR(VLOOKUP($D42,'Master Sheet'!$B:$AA,5,FALSE),"") -> 4960759904393 | K42: =IFERROR(VLOOKUP($D42,'Master Sheet'!$B:$AA,8,FALSE),"") -> 1439.955
D43: CAMNIACEP5B | G43: =IFERROR(VLOOKUP($D43,'Master Sheet'!$B:$AA,3,FALSE),"") -> EP-5B POWER CONNECTOR - D7000/D7100/D600/D610/D800/E | I43: =IFERROR(VLOOKUP($D43,'Master Sheet'!$B:$AA,2,FALSE),"") -> VEB00901 | J43: =IFERROR(VLOOKUP($D43,'Master Sheet'!$B:$AA,5,FALSE),"") -> 018208270149 | K43: =IFERROR(VLOOKUP($D43,'Master Sheet'!$B:$AA,8,FALSE),"") -> 863.955
D44: CAMNIACILCMBN10 | G44: =IFERROR(VLOOKUP($D44,'Master Sheet'!$B:$AA,3,FALSE),"") -> Nikon MB-N10 battery pack for the Z6/Z7 | I44: =IFERROR(VLOOKUP($D44,'Master Sheet'!$B:$AA,2,FALSE),"") -> VFC00801 | J44: =IFERROR(VLOOKUP($D44,'Master Sheet'!$B:$AA,5,FALSE),"") -> 018208272044 | K44: =IFERROR(VLOOKUP($D44,'Master Sheet'!$B:$AA,8,FALSE),"") -> 5039.955
D45: CAMNIACMH25A | G45: =IFERROR(VLOOKUP($D45,'Master Sheet'!$B:$AA,3,FALSE),"") -> MH-25A BATTERY CHARGER - EN-EL15 Battery | I45: =IFERROR(VLOOKUP($D45,'Master Sheet'!$B:$AA,2,FALSE),"") -> VEA016EA | J45: =IFERROR(VLOOKUP($D45,'Master Sheet'!$B:$AA,5,FALSE),"") -> 018208941704 | K45: =IFERROR(VLOOKUP($D45,'Master Sheet'!$B:$AA,8,FALSE),"") -> 1106.955
G46: =IFERROR(VLOOKUP($D46,'Master Sheet'!$B:$AA,3,FALSE),"") | I46: =IFERROR(VLOOKUP($D46,'Master Sheet'!$B:$AA,2,FALSE),"") | J46: =IFERROR(VLOOKUP($D46,'Master Sheet'!$B:$AA,5,FALSE),"") | K46: =IFERROR(VLOOKUP($D46,'Master Sheet'!$B:$AA,8,FALSE),"")
C47: Remotes & Releases
D48: CAMNIACMCDC3 | G48: =IFERROR(VLOOKUP($D48,'Master Sheet'!$B:$AA,3,FALSE),"") -> Nikon MC-DC3 Remote Release Cord | I48: =IFERROR(VLOOKUP($D48,'Master Sheet'!$B:$AA,2,FALSE),"") -> VDR01001 | J48: =IFERROR(VLOOKUP($D48,'Master Sheet'!$B:$AA,5,FALSE),"") -> No Barcode | K48: =IFERROR(VLOOKUP($D48,'Master Sheet'!$B:$AA,8,FALSE),"") -> 584.955
D49: CAMNIACWRT10 | G49: =IFERROR(VLOOKUP($D49,'Master Sheet'!$B:$AA,3,FALSE),"") -> WR-T10 WIRELESS REMOTE TRANSMITTER | I49: =IFERROR(VLOOKUP($D49,'Master Sheet'!$B:$AA,2,FALSE),"") -> VBJ003AE | J49: =IFERROR(VLOOKUP($D49,'Master Sheet'!$B:$AA,5,FALSE),"") -> 018208933525 | K49: =IFERROR(VLOOKUP($D49,'Master Sheet'!$B:$AA,8,FALSE),"") -> 1475.955
...

Sheet Z f
C3: Format
D4: FX
C5: Megapixels
D6: 24.5 MP
C7: Continuous Shooting
D8: 30 FPS
C10: ISO
D11: 100 - 64,000. ISO Expandable to 204,800
C13: Video
D14: 4K/30p and 1080/120p video
C16: Memory
D17: SD UHS-I/II/ SDHC & MicroSDHC/SDXC
C19: Monitor Size
D20: 3.2 Inch Vari-angle TFT | G20: Inspired full-frame performance
C22: Order Code | G22: Details | I22: Product Code | J22: Barcode | K22: Dealer (Export)
D24: CAMNIILCZF | G24: =IFERROR(VLOOKUP($D24,'Master Sheet'!$B:$AA,3,FALSE),"") -> Nikon Z f Mirrorless Digital Camera (Body Only) | I24: =IFERROR(VLOOKUP($D24,'Master Sheet'!$B:$AA,2,FALSE),"") -> VOA120AM | J24: =IFERROR(VLOOKUP($D24,'Master Sheet'!$B:$AA,5,FALSE),"") -> 4960759913807 | K24: =IFERROR(VLOOKUP($D24,'Master Sheet'!$B:$AA,8,FALSE),"") -> 41480.955
D25: CAMNIILCZFK001 | G25: =IFERROR(VLOOKUP($D25,'Master Sheet'!$B:$AA,3,FALSE),"") -> Nikon Z f Mirrorless Digital Camera (Body) + SmallRig L-Shape Grip 4262 | I25: =IFERROR(VLOOKUP($D25,'Master Sheet'!$B:$AA,2,FALSE),"") -> 0 | J25: =IFERROR(VLOOKUP($D25,'Master Sheet'!$B:$AA,5,FALSE),"") -> No Barcode | K25: =IFERROR(VLOOKUP($D25,'Master Sheet'!$B:$AA,8,FALSE),"") -> 41480.955
G26: =IFERROR(VLOOKUP($D26,'Master Sheet'!$B:$AA,3,FALSE),"") | I26: =IFERROR(VLOOKUP($D26,'Master Sheet'!$B:$AA,2,FALSE),"") | J26: =IFERROR(VLOOKUP($D26,'Master Sheet'!$B:$AA,5,FALSE),"") | K26: =IFERROR(VLOOKUP($D26,'Master Sheet'!$B:$AA,8,FALSE),"")
C27: Body Cap
D28: CAMNIACILCBFN1 | G28: =IFERROR(VLOOKUP($D28,'Master Sheet'!$B:$AA,3,FALSE),"") -> BF-N1 Body Cap (Z-Series) | I28: =IFERROR(VLOOKUP($D28,'Master Sheet'!$B:$AA,2,FALSE),"") -> VOD00101 | J28: =IFERROR(VLOOKUP($D28,'Master Sheet'!$B:$AA,5,FALSE),"") -> 4960759901002 | K28: =IFERROR(VLOOKUP($D28,'Master Sheet'!$B:$AA,8,FALSE),"") -> 116.955
C30: Lens Adapter
D31: CAMNIACILCFTZII | G31: =IFERROR(VLOOKUP($D31,'Master Sheet'!$B:$AA,3,FALSE),"") -> FTZ II Mount Adapter | I31: =IFERROR(VLOOKUP($D31,'Master Sheet'!$B:$AA,2,FALSE),"") -> JMA905DA | J31: =IFERROR(VLOOKUP($D31,'Master Sheet'!$B:$AA,5,FALSE),"") -> 018208042647 | K31: =IFERROR(VLOOKUP($D31,'Master Sheet'!$B:$AA,8,FALSE),"") -> 4049.955
G32: =IFERROR(VLOOKUP($D32,'Master Sheet'!$B:$AA,3,FALSE),"") | I32: =IFERROR(VLOOKUP($D32,'Master Sheet'!$B:$AA,2,FALSE),"") | J32: =IFERROR(VLOOKUP($D32,'Master Sheet'!$B:$AA,5,FALSE),"") | K32: =IFERROR(VLOOKUP($D32,'Master Sheet'!$B:$AA,8,FALSE),"")
C33: Lenses
G34: (See Mirrorless Lenses Pricelist Sheets) | I34: =IFERROR(VLOOKUP($D34,'Master Sheet'!$B:$AA,2,FALSE),"") | J34: =IFERROR(VLOOKUP($D34,'Master Sheet'!$B:$AA,5,FALSE),"") | K34: =IFERROR(VLOOKUP($D34,'Master Sheet'!$B:$AA,8,FALSE),"")
G35: =IFERROR(VLOOKUP($D35,'Master Sheet'!$B:$AA,3,FALSE),"") | I35: =IFERROR(VLOOKUP($D35,'Master Sheet'!$B:$AA,2,FALSE),"") | J35: =IFERROR(VLOOKUP($D35,'Master Sheet'!$B:$AA,5,FALSE),"") | K35: =IFERROR(VLOOKUP($D35,'Master Sheet'!$B:$AA,8,FALSE),"")
C36: Speedlights/Flashes
G37: (See Speedlight Pricelist Sheets) | I37: =IFERROR(VLOOKUP($D37,'Master Sheet'!$B:$AA,2,FALSE),"") | J37: =IFERROR(VLOOKUP($D37,'Master Sheet'!$B:$AA,5,FALSE),"") | K37: =IFERROR(VLOOKUP($D37,'Master Sheet'!$B:$AA,8,FALSE),"")
G38: =IFERROR(VLOOKUP($D38,'Master Sheet'!$B:$AA,3,FALSE),"") | I38: =IFERROR(VLOOKUP($D38,'Master Sheet'!$B:$AA,2,FALSE),"") | J38: =IFERROR(VLOOKUP($D38,'Master Sheet'!$B:$AA,5,FALSE),"") | K38: =IFERROR(VLOOKUP($D38,'Master Sheet'!$B:$AA,8,FALSE),"")
C39: Power Accessories
D40: CAMNIACMH25A | G40: =IFERROR(VLOOKUP($D40,'Master Sheet'!$B:$AA,3,FALSE),"") -> MH-25A BATTERY CHARGER - EN-EL15 Battery | I40: =IFERROR(VLOOKUP($D40,'Master Sheet'!$B:$AA,2,FALSE),"") -> VEA016EA | J40: =IFERROR(VLOOKUP($D40,'Master Sheet'!$B:$AA,5,FALSE),"") -> 018208941704 | K40: =IFERROR(VLOOKUP($D40,'Master Sheet'!$B:$AA,8,FALSE),"") -> 1106.955
D41: CAMNIACENEL15C | G41: =IFERROR(VLOOKUP($D41,'Master Sheet'!$B:$AA,3,FALSE),"") -> EN-EL15C RECHARGEABLE LI-ION BATTERY | I41: =IFERROR(VLOOKUP($D41,'Master Sheet'!$B:$AA,2,FALSE),"") -> VFB12802 | J41: =IFERROR(VLOOKUP($D41,'Master Sheet'!$B:$AA,5,FALSE),"") -> 4960759904393 | K41: =IFERROR(VLOOKUP($D41,'Master Sheet'!$B:$AA,8,FALSE),"") -> 1439.955
D42: CAMNIACILCEH7P | G42: =IFERROR(VLOOKUP($D42,'Master Sheet'!$B:$AA,3,FALSE),"") -> Charging AC Adapter EH-7P | I42: =IFERROR(VLOOKUP($D42,'Master Sheet'!$B:$AA,2,FALSE),"") -> VEB029BA | J42: =IFERROR(VLOOKUP($D42,'Master Sheet'!$B:$AA,5,FALSE),"") -> 4960759901958 | K42: =IFERROR(VLOOKUP($D42,'Master Sheet'!$B:$AA,8,FALSE),"") -> 917.955
G43: =IFERROR(VLOOKUP($D43,'Master Sheet'!$B:$AA,3,FALSE),"") | I43: =IFERROR(VLOOKUP($D43,'Master Sheet'!$B:$AA,2,FALSE),"") | J43: =IFERROR(VLOOKUP($D43,'Master Sheet'!$B:$AA,5,FALSE),"") | K43: =IFERROR(VLOOKUP($D43,'Master Sheet'!$B:$AA,8,FALSE),"")
C44: Remotes & Releases
D45: CAMNIACMLL7 | G45: =IFERROR(VLOOKUP($D45,'Master Sheet'!$B:$AA,3,FALSE),"") -> ML-L7 REMOTE CONTROL | I45: =IFERROR(VLOOKUP($D45,'Master Sheet'!$B:$AA,2,FALSE),"") -> VAJ57201 | J45: =IFERROR(VLOOKUP($D45,'Master Sheet'!$B:$AA,5,FALSE),"") -> 018208259526 | K45: =IFERROR(VLOOKUP($D45,'Master Sheet'!$B:$AA,8,FALSE),"") -> 800.955
D46: CAMNIACILMCN10 | G46: =IFERROR(VLOOKUP($D46,'Master Sheet'!$B:$AA,3,FALSE),"") -> Nikon MC-N10 Remote Grip | I46: =IFERROR(VLOOKUP($D46,'Master Sheet'!$B:$AA,2,FALSE),"") -> VDR009AA | J46: =IFERROR(VLOOKUP($D46,'Master Sheet'!$B:$AA,5,FALSE),"") -> 018208272303 | K46: =IFERROR(VLOOKUP($D46,'Master Sheet'!$B:$AA,8,FALSE),"") -> 9629.955
C48: Eyepieces
D49: CAMNIACILCDK33 | G49: =IFERROR(VLOOKUP($D49,'Master Sheet'!$B:$AA,3,FALSE),"") -> DK-33 Rubber Eyecup | I49: =IFERROR(VLOOKUP($D49,'Master Sheet'!$B:$AA,2,FALSE),"") -> VOW00501 | J49: =IFERROR(VLOOKUP($D49,'Master Sheet'!$B:$AA,5,FALSE),"") -> 018208272242 | K49: =IFERROR(VLOOKUP($D49,'Master Sheet'!$B:$AA,8,FALSE),"") -> 152.955
G50: =IFERROR(VLOOKUP($D50,'Master Sheet'!$B:$AA,3,FALSE),"") | I50: =IFERROR(VLOOKUP($D50,'Master Sheet'!$B:$AA,2,FALSE),"") | J50: =IFERROR(VLOOKUP($D50,'Master Sheet'!$B:$AA,5,FALSE),"") | K50: =IFERROR(VLOOKUP($D50,'Master Sheet'!$B:$AA,8,FALSE),"")
...

Sheet Z fc
C3: Format
D4: DX
C5: Megapixels
D6: 20.9 MP
C7: Continuous Shooting
D8: 11 FPS
C10: ISO
D11: 100 - 51,200. ISO Expandable to 204,800
C13: Video
D14: 4K/30p and 1080/120p video
C16: Memory
D17: SD UHS-I/SDHC/SDXC
C19: Monitor Size
D20: 3.2 Inch Vari-angle TFT | G20: Iconic design. Z performance.
C22: Order Code | G22: Details | I22: Product Code | J22: Barcode | K22: Dealer (Export)
D24: CAMNIILCZFC | G24: =IFERROR(VLOOKUP($D24,'Master Sheet'!$B:$AA,3,FALSE),"") -> Nikon Z fc Mirrorless Digital Camera BODY | I24: =IFERROR(VLOOKUP($D24,'Master Sheet'!$B:$AA,2,FALSE),"") -> VOA090AM | J24: =IFERROR(VLOOKUP($D24,'Master Sheet'!$B:$AA,5,FALSE),"") -> 4960759906373 | K24: =IFERROR(VLOOKUP($D24,'Master Sheet'!$B:$AA,8,FALSE),"") -> 17999.955
D25: CAMNIILCZFCK002 | G25: =IFERROR(VLOOKUP($D25,'Master Sheet'!$B:$AA,3,FALSE),"") -> Nikon Z fc Mirrorless Digital Camera / 16-50MM SILVER | I25: =IFERROR(VLOOKUP($D25,'Master Sheet'!$B:$AA,2,FALSE),"") -> 0 | J25: =IFERROR(VLOOKUP($D25,'Master Sheet'!$B:$AA,5,FALSE),"") -> 6009658262482 | K25: =IFERROR(VLOOKUP($D25,'Master Sheet'!$B:$AA,8,FALSE),"") -> 21131.955
G26: =IFERROR(VLOOKUP($D26,'Master Sheet'!$B:$AA,3,FALSE),"") | I26: =IFERROR(VLOOKUP($D26,'Master Sheet'!$B:$AA,2,FALSE),"") | J26: =IFERROR(VLOOKUP($D26,'Master Sheet'!$B:$AA,5,FALSE),"") | K26: =IFERROR(VLOOKUP($D26,'Master Sheet'!$B:$AA,8,FALSE),"")
C27: Body Cap
D28: CAMNIACILCBFN1 | G28: =IFERROR(VLOOKUP($D28,'Master Sheet'!$B:$AA,3,FALSE),"") -> BF-N1 Body Cap (Z-Series) | I28: =IFERROR(VLOOKUP($D28,'Master Sheet'!$B:$AA,2,FALSE),"") -> VOD00101 | J28: =IFERROR(VLOOKUP($D28,'Master Sheet'!$B:$AA,5,FALSE),"") -> 4960759901002 | K28: =IFERROR(VLOOKUP($D28,'Master Sheet'!$B:$AA,8,FALSE),"") -> 116.955
C30: Lens Adapter
D31: CAMNIACILCFTZII | G31: =IFERROR(VLOOKUP($D31,'Master Sheet'!$B:$AA,3,FALSE),"") -> FTZ II Mount Adapter | I31: =IFERROR(VLOOKUP($D31,'Master Sheet'!$B:$AA,2,FALSE),"") -> JMA905DA | J31: =IFERROR(VLOOKUP($D31,'Master Sheet'!$B:$AA,5,FALSE),"") -> 018208042647 | K31: =IFERROR(VLOOKUP($D31,'Master Sheet'!$B:$AA,8,FALSE),"") -> 4049.955
G32: =IFERROR(VLOOKUP($D32,'Master Sheet'!$B:$AA,3,FALSE),"") | I32: =IFERROR(VLOOKUP($D32,'Master Sheet'!$B:$AA,2,FALSE),"") | J32: =IFERROR(VLOOKUP($D32,'Master Sheet'!$B:$AA,5,FALSE),"") | K32: =IFERROR(VLOOKUP($D32,'Master Sheet'!$B:$AA,8,FALSE),"")
C33: Lenses
G34: (See Mirrorless Lenses Pricelist Sheets) | I34: =IFERROR(VLOOKUP($D34,'Master Sheet'!$B:$AA,2,FALSE),"") | J34: =IFERROR(VLOOKUP($D34,'Master Sheet'!$B:$AA,5,FALSE),"") | K34: =IFERROR(VLOOKUP($D34,'Master Sheet'!$B:$AA,8,FALSE),"")
G35: =IFERROR(VLOOKUP($D35,'Master Sheet'!$B:$AA,3,FALSE),"") | I35: =IFERROR(VLOOKUP($D35,'Master Sheet'!$B:$AA,2,FALSE),"") | J35: =IFERROR(VLOOKUP($D35,'Master Sheet'!$B:$AA,5,FALSE),"") | K35: =IFERROR(VLOOKUP($D35,'Master Sheet'!$B:$AA,8,FALSE),"")
C36: Speedlights/Flashes
G37: (See Speedlight Pricelist Sheets) | I37: =IFERROR(VLOOKUP($D37,'Master Sheet'!$B:$AA,2,FALSE),"") | J37: =IFERROR(VLOOKUP($D37,'Master Sheet'!$B:$AA,5,FALSE),"") | K37: =IFERROR(VLOOKUP($D37,'Master Sheet'!$B:$AA,8,FALSE),"")
G38: =IFERROR(VLOOKUP($D38,'Master Sheet'!$B:$AA,3,FALSE),"") | I38: =IFERROR(VLOOKUP($D38,'Master Sheet'!$B:$AA,2,FALSE),"") | J38: =IFERROR(VLOOKUP($D38,'Master Sheet'!$B:$AA,5,FALSE),"") | K38: =IFERROR(VLOOKUP($D38,'Master Sheet'!$B:$AA,8,FALSE),"")
C39: Power Accessories
D40: CAMNIACILCMH32 | G40: =IFERROR(VLOOKUP($D40,'Master Sheet'!$B:$AA,3,FALSE),"") -> MH-32 Battery Charger | I40: =IFERROR(VLOOKUP($D40,'Master Sheet'!$B:$AA,2,FALSE),"") -> VEA024EB | J40: =IFERROR(VLOOKUP($D40,'Master Sheet'!$B:$AA,5,FALSE),"") -> 4960759904300 | K40: =IFERROR(VLOOKUP($D40,'Master Sheet'!$B:$AA,8,FALSE),"") -> 917.955
D41: CAMNIACENEL25 | G41: =IFERROR(VLOOKUP($D41,'Master Sheet'!$B:$AA,3,FALSE),"") -> EN-EL25 RECHARGEABLE LI-ION BATTERY | I41: =IFERROR(VLOOKUP($D41,'Master Sheet'!$B:$AA,2,FALSE),"") -> VFB12502 | J41: =IFERROR(VLOOKUP($D41,'Master Sheet'!$B:$AA,5,FALSE),"") -> 4960759903976 | K41: =IFERROR(VLOOKUP($D41,'Master Sheet'!$B:$AA,8,FALSE),"") -> 1574.955
D42: CAMNIACILCEH7P | G42: =IFERROR(VLOOKUP($D42,'Master Sheet'!$B:$AA,3,FALSE),"") -> Charging AC Adapter EH-7P | I42: =IFERROR(VLOOKUP($D42,'Master Sheet'!$B:$AA,2,FALSE),"") -> VEB029BA | J42: =IFERROR(VLOOKUP($D42,'Master Sheet'!$B:$AA,5,FALSE),"") -> 4960759901958 | K42: =IFERROR(VLOOKUP($D42,'Master Sheet'!$B:$AA,8,FALSE),"") -> 917.955
G43: =IFERROR(VLOOKUP($D43,'Master Sheet'!$B:$AA,3,FALSE),"") | I43: =IFERROR(VLOOKUP($D43,'Master Sheet'!$B:$AA,2,FALSE),"") | J43: =IFERROR(VLOOKUP($D43,'Master Sheet'!$B:$AA,5,FALSE),"") | K43: =IFERROR(VLOOKUP($D43,'Master Sheet'!$B:$AA,8,FALSE),"")
C44: Remotes & Releases
D45: CAMNIACMLL7 | G45: =IFERROR(VLOOKUP($D45,'Master Sheet'!$B:$AA,3,FALSE),"") -> ML-L7 REMOTE CONTROL | I45: =IFERROR(VLOOKUP($D45,'Master Sheet'!$B:$AA,2,FALSE),"") -> VAJ57201 | J45: =IFERROR(VLOOKUP($D45,'Master Sheet'!$B:$AA,5,FALSE),"") -> 018208259526 | K45: =IFERROR(VLOOKUP($D45,'Master Sheet'!$B:$AA,8,FALSE),"") -> 800.955
G46: =IFERROR(VLOOKUP($D46,'Master Sheet'!$B:$AA,3,FALSE),"") | I46: =IFERROR(VLOOKUP($D46,'Master Sheet'!$B:$AA,2,FALSE),"") | J46: =IFERROR(VLOOKUP($D46,'Master Sheet'!$B:$AA,5,FALSE),"") | K46: =IFERROR(VLOOKUP($D46,'Master Sheet'!$B:$AA,8,FALSE),"")
C47: Eyepieces
D48: CAMNIACILCDK32 | G48: =IFERROR(VLOOKUP($D48,'Master Sheet'!$B:$AA,3,FALSE),"") -> DK-32 Rubber Eyecup | I48: =IFERROR(VLOOKUP($D48,'Master Sheet'!$B:$AA,2,FALSE),"") -> 0 | J48: =IFERROR(VLOOKUP($D48,'Master Sheet'!$B:$AA,5,FALSE),"") -> No Barcode | K48: =IFERROR(VLOOKUP($D48,'Master Sheet'!$B:$AA,8,FALSE),"") -> TBC
G49: =IFERROR(VLOOKUP($D49,'Master Sheet'!$B:$AA,3,FALSE),"") | I49: =IFERROR(VLOOKUP($D49,'Master Sheet'!$B:$AA,2,FALSE),"") | J49: =IFERROR(VLOOKUP($D49,'Master Sheet'!$B:$AA,5,FALSE),"") | K49: =IFERROR(VLOOKUP($D49,'Master Sheet'!$B:$AA,8,FALSE),"")
...

Sheet Z50 II
C3: Format
D4: DX
C5: Megapixels
D6: 20.9 MP
C7: Continuous Shooting
D8: 30 FPS
C10: ISO
D11: 100 - 51,200. ISO Expandable to 204,800
C13: Video
D14: 4K/30p and 1080/120p video
C16: Memory
D17: SD UHS-II/SDHC/SDXC
C19: Monitor Size
D20: 3.2 Inch Tilt Touch-LCD | G20: Insanely small. Amazingly bold.
C22: Order Code | G22: Details | I22: Product Code | J22: Barcode | K22: Dealer (Export)
D24: CAMNIILCZ50II | G24: =IFERROR(VLOOKUP($D24,'Master Sheet'!$B:$AA,3,FALSE),"") -> Nikon Z50 II Mirrorless Digital Camera (Body Only) | I24: =IFERROR(VLOOKUP($D24,'Master Sheet'!$B:$AA,2,FALSE),"") -> VOA150AM | J24: =IFERROR(VLOOKUP($D24,'Master Sheet'!$B:$AA,5,FALSE),"") -> 4960759916785 | K24: =IFERROR(VLOOKUP($D24,'Master Sheet'!$B:$AA,8,FALSE),"") -> 16433.955
D25: CAMNIILCZ50IIK001 | G25: =IFERROR(VLOOKUP($D25,'Master Sheet'!$B:$AA,3,FALSE),"") -> Nikon Z50 II Single Kit: 16-50MM f3.5-6.3 VR DX Lens+Bag 6009658263847 | I25: =IFERROR(VLOOKUP($D25,'Master Sheet'!$B:$AA,2,FALSE),"") -> 0 | J25: =IFERROR(VLOOKUP($D25,'Master Sheet'!$B:$AA,5,FALSE),"") -> 6009658263847 | K25: =IFERROR(VLOOKUP($D25,'Master Sheet'!$B:$AA,8,FALSE),"") -> 19574.955
D26: CAMNIILCZ50IIK002 | G26: =IFERROR(VLOOKUP($D26,'Master Sheet'!$B:$AA,3,FALSE),"") -> Nikon Z50 II Twin Kit: 16-50MM f3.5-6.3 VR DX+50-250MM F4.5-6.3 VR DX Lens+Bag+Card 6009658263854 | I26: =IFERROR(VLOOKUP($D26,'Master Sheet'!$B:$AA,2,FALSE),"") -> 0 | J26: =IFERROR(VLOOKUP($D26,'Master Sheet'!$B:$AA,5,FALSE),"") -> 6009658263854 | K26: =IFERROR(VLOOKUP($D26,'Master Sheet'!$B:$AA,8,FALSE),"") -> 25046.955
D27: CAMNIILCZ50IIK003 | G27: =IFERROR(VLOOKUP($D27,'Master Sheet'!$B:$AA,3,FALSE),"") -> Nikon Z50 II Trip Kti: 16-50MM f3.5-6.3+50-250MM f4.5-6.3+35MM f1.4 Lens+Bag+Card 6009658263861 | I27: =IFERROR(VLOOKUP($D27,'Master Sheet'!$B:$AA,2,FALSE),"") -> 0 | J27: =IFERROR(VLOOKUP($D27,'Master Sheet'!$B:$AA,5,FALSE),"") -> 6009658263861 | K27: =IFERROR(VLOOKUP($D27,'Master Sheet'!$B:$AA,8,FALSE),"") -> 33659.955
D28: CAMNIILCZ50IIK004 | G28: =IFERROR(VLOOKUP($D28,'Master Sheet'!$B:$AA,3,FALSE),"") -> Nikon Z50 II Creator Kit: 16-50MM f3.5-6.3 VR DX Lens+Bag+Card+ML-L7+Tripod+Mic 6009658263878 | I28: =IFERROR(VLOOKUP($D28,'Master Sheet'!$B:$AA,2,FALSE),"") -> 0 | J28: =IFERROR(VLOOKUP($D28,'Master Sheet'!$B:$AA,5,FALSE),"") -> 6009658263878 | K28: =IFERROR(VLOOKUP($D28,'Master Sheet'!$B:$AA,8,FALSE),"") -> 21914.955
D29: CAMNIILCZ50IIK005 | G29: =IFERROR(VLOOKUP($D29,'Master Sheet'!$B:$AA,3,FALSE),"") -> Nikon Z50 II Vlogging Kit: 35mm F1.4 Lens+Bag+Card+ML-L7+Tripod+Mic 6009658263885 | I29: =IFERROR(VLOOKUP($D29,'Master Sheet'!$B:$AA,2,FALSE),"") -> 0 | J29: =IFERROR(VLOOKUP($D29,'Master Sheet'!$B:$AA,5,FALSE),"") -> 6009658263885 | K29: =IFERROR(VLOOKUP($D29,'Master Sheet'!$B:$AA,8,FALSE),"") -> 28961.955
G30: =IFERROR(VLOOKUP($D30,'Master Sheet'!$B:$AA,3,FALSE),"") | I30: =IFERROR(VLOOKUP($D30,'Master Sheet'!$B:$AA,2,FALSE),"") | J30: =IFERROR(VLOOKUP($D30,'Master Sheet'!$B:$AA,5,FALSE),"") | K30: =IFERROR(VLOOKUP($D30,'Master Sheet'!$B:$AA,8,FALSE),"")
C31: Body Cap
D32: CAMNIACILCBFN1 | G32: =IFERROR(VLOOKUP($D32,'Master Sheet'!$B:$AA,3,FALSE),"") -> BF-N1 Body Cap (Z-Series) | I32: =IFERROR(VLOOKUP($D32,'Master Sheet'!$B:$AA,2,FALSE),"") -> VOD00101 | J32: =IFERROR(VLOOKUP($D32,'Master Sheet'!$B:$AA,5,FALSE),"") -> 4960759901002 | K32: =IFERROR(VLOOKUP($D32,'Master Sheet'!$B:$AA,8,FALSE),"") -> 116.955
C34: Lens Adapter
D35: CAMNIACILCFTZII | G35: =IFERROR(VLOOKUP($D35,'Master Sheet'!$B:$AA,3,FALSE),"") -> FTZ II Mount Adapter | I35: =IFERROR(VLOOKUP($D35,'Master Sheet'!$B:$AA,2,FALSE),"") -> JMA905DA | J35: =IFERROR(VLOOKUP($D35,'Master Sheet'!$B:$AA,5,FALSE),"") -> 018208042647 | K35: =IFERROR(VLOOKUP($D35,'Master Sheet'!$B:$AA,8,FALSE),"") -> 4049.955
G36: =IFERROR(VLOOKUP($D36,'Master Sheet'!$B:$AA,3,FALSE),"") | I36: =IFERROR(VLOOKUP($D36,'Master Sheet'!$B:$AA,2,FALSE),"") | J36: =IFERROR(VLOOKUP($D36,'Master Sheet'!$B:$AA,5,FALSE),"") | K36: =IFERROR(VLOOKUP($D36,'Master Sheet'!$B:$AA,8,FALSE),"")
C37: Lenses
G38: (See Mirrorless Lenses Pricelist Sheets) | I38: =IFERROR(VLOOKUP($D38,'Master Sheet'!$B:$AA,2,FALSE),"") | J38: =IFERROR(VLOOKUP($D38,'Master Sheet'!$B:$AA,5,FALSE),"") | K38: =IFERROR(VLOOKUP($D38,'Master Sheet'!$B:$AA,8,FALSE),"")
G39: =IFERROR(VLOOKUP($D39,'Master Sheet'!$B:$AA,3,FALSE),"") | I39: =IFERROR(VLOOKUP($D39,'Master Sheet'!$B:$AA,2,FALSE),"") | J39: =IFERROR(VLOOKUP($D39,'Master Sheet'!$B:$AA,5,FALSE),"") | K39: =IFERROR(VLOOKUP($D39,'Master Sheet'!$B:$AA,8,FALSE),"")
C40: Speedlights/Flashes
G41: (See Speedlight Pricelist Sheets) | I41: =IFERROR(VLOOKUP($D41,'Master Sheet'!$B:$AA,2,FALSE),"") | J41: =IFERROR(VLOOKUP($D41,'Master Sheet'!$B:$AA,5,FALSE),"") | K41: =IFERROR(VLOOKUP($D41,'Master Sheet'!$B:$AA,8,FALSE),"")
G42: =IFERROR(VLOOKUP($D42,'Master Sheet'!$B:$AA,3,FALSE),"") | I42: =IFERROR(VLOOKUP($D42,'Master Sheet'!$B:$AA,2,FALSE),"") | J42: =IFERROR(VLOOKUP($D42,'Master Sheet'!$B:$AA,5,FALSE),"") | K42: =IFERROR(VLOOKUP($D42,'Master Sheet'!$B:$AA,8,FALSE),"")
C43: Power Accessories
D44: CAMNIACILCMH32 | G44: =IFERROR(VLOOKUP($D44,'Master Sheet'!$B:$AA,3,FALSE),"") -> MH-32 Battery Charger | I44: =IFERROR(VLOOKUP($D44,'Master Sheet'!$B:$AA,2,FALSE),"") -> VEA024EB | J44: =IFERROR(VLOOKUP($D44,'Master Sheet'!$B:$AA,5,FALSE),"") -> 4960759904300 | K44: =IFERROR(VLOOKUP($D44,'Master Sheet'!$B:$AA,8,FALSE),"") -> 917.955
D45: CAMNIACENEL25A | G45: =IFERROR(VLOOKUP($D45,'Master Sheet'!$B:$AA,3,FALSE),"") -> EN-EL25A RECHARGEABLE LI-ION BATTERY | I45: =IFERROR(VLOOKUP($D45,'Master Sheet'!$B:$AA,2,FALSE),"") -> 0 | J45: =IFERROR(VLOOKUP($D45,'Master Sheet'!$B:$AA,5,FALSE),"") -> No Barcode | K45: =IFERROR(VLOOKUP($D45,'Master Sheet'!$B:$AA,8,FALSE),"") -> 1574.955
G46: =IFERROR(VLOOKUP($D46,'Master Sheet'!$B:$AA,3,FALSE),"") | I46: =IFERROR(VLOOKUP($D46,'Master Sheet'!$B:$AA,2,FALSE),"") | J46: =IFERROR(VLOOKUP($D46,'Master Sheet'!$B:$AA,5,FALSE),"") | K46: =IFERROR(VLOOKUP($D46,'Master Sheet'!$B:$AA,8,FALSE),"")
C47: Remotes & Releases
D48: CAMNIACMLL7 | G48: =IFERROR(VLOOKUP($D48,'Master Sheet'!$B:$AA,3,FALSE),"") -> ML-L7 REMOTE CONTROL | I48: =IFERROR(VLOOKUP($D48,'Master Sheet'!$B:$AA,2,FALSE),"") -> VAJ57201 | J48: =IFERROR(VLOOKUP($D48,'Master Sheet'!$B:$AA,5,FALSE),"") -> 018208259526 | K48: =IFERROR(VLOOKUP($D48,'Master Sheet'!$B:$AA,8,FALSE),"") -> 800.955
D49: CAMNIACILMCN10 | G49: =IFERROR(VLOOKUP($D49,'Master Sheet'!$B:$AA,3,FALSE),"") -> Nikon MC-N10 Remote Grip | I49: =IFERROR(VLOOKUP($D49,'Master Sheet'!$B:$AA,2,FALSE),"") -> VDR009AA | J49: =IFERROR(VLOOKUP($D49,'Master Sheet'!$B:$AA,5,FALSE),"") -> 018208272303 | K49: =IFERROR(VLOOKUP($D49,'Master Sheet'!$B:$AA,8,FALSE),"") -> 9629.955
...

Sheet Z30
C3: Format
D4: DX
C5: Megapixels
D6: 20.9 MP
C7: Continuous Shooting
D8: 11 FPS
C10: ISO
D11: 100 - 51,200. ISO Expandable to 204,800
C13: Video
D14: 4K/30p and 1080/120p video
C16: Memory
D17: SD UHS-I/SDHC/SDXC
C19: Monitor Size
D20: 3.2 Inch Tilt Touch-LCD | G20: Creator ready.
C22: Order Code | G22: Details | I22: Product Code | J22: Barcode | K22: Dealer (Export)
D24: CAMNIILCZ30 | G24: =IFERROR(VLOOKUP($D24,'Master Sheet'!$B:$AA,3,FALSE),"") -> Nikon Z30 Mirrorless Digital Camera (Body Only) | I24: =IFERROR(VLOOKUP($D24,'Master Sheet'!$B:$AA,2,FALSE),"") -> VOA110AM | J24: =IFERROR(VLOOKUP($D24,'Master Sheet'!$B:$AA,5,FALSE),"") -> 4960759913593 | K24: =IFERROR(VLOOKUP($D24,'Master Sheet'!$B:$AA,8,FALSE),"") -> 13697.955
D25: CAMNIILCZ30K001 | G25: =IFERROR(VLOOKUP($D25,'Master Sheet'!$B:$AA,3,FALSE),"") -> Nikon Z30 Mirrorless Digital Camera +16-50MM f3.5-6.3 VR DX | I25: =IFERROR(VLOOKUP($D25,'Master Sheet'!$B:$AA,2,FALSE),"") -> 0 | J25: =IFERROR(VLOOKUP($D25,'Master Sheet'!$B:$AA,5,FALSE),"") -> 6009658263250 | K25: =IFERROR(VLOOKUP($D25,'Master Sheet'!$B:$AA,8,FALSE),"") -> 16829.955
G26: =IFERROR(VLOOKUP($D26,'Master Sheet'!$B:$AA,3,FALSE),"") | I26: =IFERROR(VLOOKUP($D26,'Master Sheet'!$B:$AA,2,FALSE),"") | J26: =IFERROR(VLOOKUP($D26,'Master Sheet'!$B:$AA,5,FALSE),"") | K26: =IFERROR(VLOOKUP($D26,'Master Sheet'!$B:$AA,8,FALSE),"")
C27: Body Cap
D28: CAMNIACILCBFN1 | G28: =IFERROR(VLOOKUP($D28,'Master Sheet'!$B:$AA,3,FALSE),"") -> BF-N1 Body Cap (Z-Series) | I28: =IFERROR(VLOOKUP($D28,'Master Sheet'!$B:$AA,2,FALSE),"") -> VOD00101 | J28: =IFERROR(VLOOKUP($D28,'Master Sheet'!$B:$AA,5,FALSE),"") -> 4960759901002 | K28: =IFERROR(VLOOKUP($D28,'Master Sheet'!$B:$AA,8,FALSE),"") -> 116.955
C30: Lens Adapter
D31: CAMNIACILCFTZII | G31: =IFERROR(VLOOKUP($D31,'Master Sheet'!$B:$AA,3,FALSE),"") -> FTZ II Mount Adapter | I31: =IFERROR(VLOOKUP($D31,'Master Sheet'!$B:$AA,2,FALSE),"") -> JMA905DA | J31: =IFERROR(VLOOKUP($D31,'Master Sheet'!$B:$AA,5,FALSE),"") -> 018208042647 | K31: =IFERROR(VLOOKUP($D31,'Master Sheet'!$B:$AA,8,FALSE),"") -> 4049.955
G32: =IFERROR(VLOOKUP($D32,'Master Sheet'!$B:$AA,3,FALSE),"") | I32: =IFERROR(VLOOKUP($D32,'Master Sheet'!$B:$AA,2,FALSE),"") | J32: =IFERROR(VLOOKUP($D32,'Master Sheet'!$B:$AA,5,FALSE),"") | K32: =IFERROR(VLOOKUP($D32,'Master Sheet'!$B:$AA,8,FALSE),"")
C33: Lenses
G34: (See Mirrorless Lenses Pricelist Sheets) | I34: =IFERROR(VLOOKUP($D34,'Master Sheet'!$B:$AA,2,FALSE),"") | J34: =IFERROR(VLOOKUP($D34,'Master Sheet'!$B:$AA,5,FALSE),"") | K34: =IFERROR(VLOOKUP($D34,'Master Sheet'!$B:$AA,8,FALSE),"")
